Workbook

Sheet Portugal_indicadores
A1: DATE | B1: Bananas | C1: Bananas s/prod22 | D1: Proj_Bananas | E1: Proj_Bananas 2 | F1: Proj_Bananas_Eloi | G1: Bananas actuel | H1: GDP | I1: Inflation | J1: Unemployment_Rate | K1: LT_Interest_Rate | L1: ST_Interest_RateE3m | M1: Euribor1year | P1: Idmes | Q1: Quarter | R1: GDP | S1: Inflation | T1: Unemployment_Rate | U1: LT_Interest_Rate | V1: ST_Interest_Rate | W1: Euribor1year
A2: 201907 | H2: =+gdp!D13 -> 0.4 | I2: -0.7 | J2: 6.6 | K2: 0.44 | L2: -0.3649 | M2: -0.2833 | P2: 2023-11 | R2: =+H54 -> 0.6 | S2: =+I54 -> 2.2 | T2: =+J54 -> 6.7 | U2: =+K54 -> 3.3 | V2: =+L54 -> 3.97 | W2: =+M54 -> 4.0221
A3: 201908 | H3: =+H2 -> 0.4 | I3: -0.1 | J3: 6.5 | K3: 0.17 | L3: -0.4077 | M3: -0.3563 | P3: 2023-12 | R3: =+H55 -> 0.6 | S3: =+I55 -> 1.9 | T3: =+J55 -> 6.7 | U3: =+K55 -> 2.85 | V3: =+L55 -> 3.93 | W3: =+M55 -> 3.6699
A4: 201909 | H4: =+H2 -> 0.4 | I4: -0.3 | J4: 6.6 | K4: 0.2 | L4: -0.4176 | M4: -0.3391 | P4: 2024-1 | R4: =+H56 -> 0.6 | S4: =+I56 -> 2.5 | T4: =+J56 -> 6.8 | U4: =+K56 -> 2.97 | V4: =+L56 -> 3.93 | W4: =+M56 -> 3.6092
A5: 201910 | H5: =+gdp!D14 -> 0.8 | I5: -0.1 | J5: 6.6 | K5: 0.19 | L5: -0.4129 | M5: -0.3042 | P5: 2024-2 | R5: =+H57 -> 0.6 | S5: =+I57 -> 2.3 | T5: =+J57 -> 6.8 | U5: =+K57 -> 3.06 | V5: =+L57 -> 3.92 | W5: =+M57 -> 3.6705
A6: 201911 | H6: =+H5 -> 0.8 | I6: 0.2 | J6: 6.8 | K6: 0.35 | L6: -0.4013 | M6: -0.272 | P6: 2024-3 | Q6: 2024-Q1 | R6: =+H58 -> 0.6 | S6: =+I58 -> 2.6 | T6: 6.3294895 | U6: =+K58 -> 3.02 | V6: =+L58 -> 3.92 | W6: =+M58 -> 3.7162
A7: 201912 | H7: =+H5 -> 0.8 | I7: 0.4 | J7: 6.9 | K7: 0.41 | L7: -0.3947 | M7: -0.2614 | P7: 2024-4 | R7: =+H59 -> 0.4 | S7: =+I59 -> 2.3 | T7: 6.3409448 | U7: =+K59 -> 3.13 | V7: =+L59 -> 3.89 | W7: =+M59 -> 3.7025
A8: 202001 | H8: =+gdp!D15 -> -4.2 | I8: 0.8 | J8: 6.9 | K8: 0.37 | L8: -0.3911 | M8: -0.2534 | P8: 2024-5 | R8: =+H60 -> 0.4 | S8: =+I60 -> 3.8 | T8: 6.3409448 | U8: =+K60 -> 3.16 | V8: =+L60 -> 3.81 | W8: =+M60 -> 3.6821
A9: 202002 | H9: =+H8 -> -4.2 | I9: 0.5 | J9: 6.5 | K9: 0.25 | L9: -0.4088 | M9: -0.2881 | P9: 2024-6 | Q9: 2024-Q2 | R9: =+H61 -> 0.4 | S9: =+I61 -> 3.1 | T9: 6.3409448 | U9: =+K61 -> 3.19 | V9: =+L61 -> 3.72 | W9: =+M61 -> 3.6496
A10: 202003 | H10: =+H9 -> -4.2 | I10: 0.1 | J10: 6.3 | K10: 0.71 | L10: -0.4166 | M10: -0.2656 | P10: 2024-7 | R10: =+H62 -> 0.4 | S10: =+I62 -> 2.7 | T10: 6.3515313 | U10: =+K62 -> 3.1 | V10: =+L62 -> 3.68 | W10: =+M62 -> 3.5259
A11: 202004 | H11: =+gdp!D16 -> -15 | I11: -0.1 | J11: 6.4 | K11: 0.97 | L11: -0.254 | M11: -0.1082 | P11: 2024-8 | R11: =+H63 -> 0.4 | S11: =+I63 -> 1.8 | T11: 6.3515313 | U11: =+K63 -> 2.88 | V11: =+L63 -> 3.55 | W11: 2.239
A12: 202005 | H12: =+H11 -> -15 | I12: -0.6 | J12: 6 | K12: 0.81 | L12: -0.272 | M12: -0.0814 | P12: 2024-9 | Q12: 2024-Q3 | R12: =+H64 -> 0.4 | S12: =+I64 -> 2.6 | T12: 6.3515313 | U12: =+K64 -> 2.78 | V12: =+L64 -> 3.43 | W12: 2.239 | Y12: EURIBOR Forecast By Month. | Z12: Updated: 2024/11/22. | AA12: EURIBOR FORECAST 2024, 2025, 2026 - Long Forecast | AG12: EURIBOR Forecast By Month. | AH12: Updated: 2025/08/19. | AJ12: EURIBOR FORECAST 2024, 2025, 2026 - Long Forecast
A13: 202006 | H13: =+H12 -> -15 | I13: 0.2 | J13: 7.5 | K13: 0.53 | L13: -0.376 | M13: -0.1475 | P13: 2024-10 | R13: =+H65 -> 1.4 | S13: =+I65 -> 2.6 | T13: 6.352873 | U13: 2.937713 | V13: =+L65 -> 3.17 | W13: 2.239 | Y13: Month | Z13: Open | AA13: Low-High,%% | AB13: Rate,% | AC13: Tot,Ch | AG13: Month | AH13: Open | AI13: Low-High,%% | AJ13: Rate,% | AK13: Tot.Ch
A14: 202007 | B14: =+[1]Grafico_avec_FWL!AE5 -> 0.043437442 | C14: =B14 -> 0.043437442 | G14: =+[1]Grafico_avec_FWL!AD5 -> 0.039518039 | H14: =+gdp!D17 -> 14.4 | I14: -0.1 | J14: 8.2 | K14: 0.4 | L14: -0.4441 | M14: -0.2789 | P14: 2024-11 | R14: =+H66 -> 1.4 | S14: 3.0129637 | T14: 6.352873 | U14: 2.937713 | V14: 3.4236147 | W14: =+Z15 -> 2.547 | Y14: 2024 | AG14: 2025
A15: 202008 | B15: =+[1]Grafico_avec_FWL!AE6 -> 0.040133947 | C15: =B15 -> 0.040133947 | G15: =+[1]Grafico_avec_FWL!AD6 -> 0.039518039 | H15: =+H14 -> 14.4 | I15: -0.2 | J15: 8.3 | K15: 0.36 | L15: -0.4797 | M15: -0.3589 | P15: 2024-12 | Q15: 2024-Q4 | R15: =+H67 -> 1.4 | S15: 3.0129637 | T15: 6.352873 | U15: 2.937713 | V15: 3.4236147 | W15: =+Z16 -> 2.488 | Y15: Nov | Z15: 2.547 | AA15: 2,339-2,704 | AB15: 2.488 | AC15: -0.059 | AG15: Aug | AH15: 2.126 | AI15: 1.920-2.192 | AJ15: 2.056 | AK15: -0.07
A16: 202009 | B16: =+[1]Grafico_avec_FWL!AE7 -> 0.040497163 | C16: =B16 -> 0.040497163 | G16: =+[1]Grafico_avec_FWL!AD7 -> 0.039518039 | H16: =+H15 -> 14.4 | I16: -0.8 | J16: 8.1 | K16: 0.32 | L16: -0.4914 | M16: -0.4146 | P16: 2025-01 | R16: =+H68 -> -0.4 | S16: 2.5845929 | T16: 6.3407056 | U16: 2.917713 | V16: 3.1736147 | W16: =+Z18 -> 2.485 | Y16: Dec | Z16: 2.488 | AA16: 2,154-2,636 | AB16: 2.485 | AC16: -0.062 | AG16: Sep | AH16: 2.056 | AI16: 1.900-2.279 | AJ16: 2.021 | AK16: -0.105
A17: 202010 | B17: =+[1]Grafico_avec_FWL!AE8 -> 0.041286086 | C17: =B17 -> 0.041286086 | G17: =+[1]Grafico_avec_FWL!AD8 -> 0.039518039 | H17: =+gdp!D18 -> 0.2 | I17: -0.6 | J17: 7.6 | K17: 0.18 | L17: -0.5091 | M17: -0.466 | P17: 2025-02 | R17: =+H69 -> -0.4 | S17: 2.5845929 | T17: 6.3407056 | U17: 2.917713 | V17: 3.1736147 | W17: =+Z19 -> 2.336 | Y17: 2025 | AG17: Oct | AH17: 2.021 | AI17: 1.950-2.198 | AJ17: 2.074 | AK17: -0.052
A18: 202011 | B18: =+[1]Grafico_avec_FWL!AE9 -> 0.042187943 | C18: =B18 -> 0.042187943 | G18: =+[1]Grafico_avec_FWL!AD9 -> 0.039518039 | H18: =+H17 -> 0.2 | I18: -0.4 | J18: 7.2 | K18: 0.07 | L18: -0.5209 | M18: -0.4806 | P18: 2025-03 | Q18: 2025-Q1 | R18: =+H70 -> -0.4 | S18: 2.5845929 | T18: 6.3407056 | U18: 2.917713 | V18: 3.1736147 | W18: =+Z20 -> 2.196 | Y18: Jan | Z18: 2.485 | AA18: 2,196-2,485 | AB18: 2.336 | AC18: -0.211 | AG18: Nov | AH18: 2.074 | AI18: 1.933-2.179 | AJ18: 2.056 | AK18: -0.07
A19: 202012 | B19: =+[1]Grafico_avec_FWL!AE10 -> 0.0424713 | C19: =B19 -> 0.0424713 | G19: =+[1]Grafico_avec_FWL!AD10 -> 0.039518039 | H19: =+H18 -> 0.2 | I19: -0.3 | J19: 6.9 | K19: 0.03 | L19: -0.5381 | M19: -0.4966 | P19: 2025-04 | R19: =+H71 -> 0.6 | S19: 2.4013153 | T19: 6.3032606 | U19: 2.887713 | V19: 2.9236147 | W19: =+Z21 -> 2.064 | Y19: Feb | Z19: 2.336 | AA19: 2,064-2,336 | AB19: 2.196 | AC19: -0.351 | AG19: Dec | AH19: 2.056 | AI19: 1.971-2.223 | AJ19: 2.097 | AK19: -0.029
A20: 202101 | B20: =+[1]Grafico_avec_FWL!AE11 -> 0.041920835 | C20: =B20 -> 0.041920835 | G20: =+[1]Grafico_avec_FWL!AD11 -> 0.039518039 | H20: =+gdp!D19 -> -2.8 | I20: 0.2 | J20: 7 | K20: 0.03 | L20: -0.5472 | M20: -0.5047 | P20: 2025-05 | R20: =+H72 -> 0.6 | S20: 2.4013153 | T20: 6.3032606 | U20: 2.887713 | V20: 2.9236147 | W20: =+Z22 -> 1.956 | Y20: Mar | Z20: 2.196 | AA20: 1,940-2,196 | AB20: 2.064 | AC20: -0.483 | AG20: 2026
A21: 202102 | B21: =+[1]Grafico_avec_FWL!AE12 -> 0.039108571 | C21: =B21 -> 0.039108571 | G21: =+[1]Grafico_avec_FWL!AD12 -> 0.039518039 | H21: =+H20 -> -2.8 | I21: 0.3 | J21: 7 | K21: 0.16 | L21: -0.5411 | M21: -0.5009 | P21: 2025-06 | Q21: 2025-Q2 | R21: =+H73 -> 0.6 | S21: 2.4013153 | T21: 6.3032606 | U21: 2.887713 | V21: 2.9236147 | W21: =+Z23 -> 1.886 | X21: updated version | Y21: Apr | Z21: 2.064 | AA21: 1,839-2,073 | AB21: 1.956 | AC21: -0.591 | AG21: Jan | AH21: 2.097 | AI21: 1.853-2.097 | AJ21: 1.971 | AK21: -0.155
A22: 202103 | B22: =+[1]Grafico_avec_FWL!AE13 -> 0.036046842 | C22: =B22 -> 0.036046842 | G22: =+[1]Grafico_avec_FWL!AD13 -> 0.039518039 | H22: =+H21 -> -2.8 | I22: 0.1 | J22: 6.8 | K22: 0.23 | L22: -0.5391 | M22: -0.4867 | P22: 2025-07 | R22: =+R23 -> 1.85 | S22: 2.3199071 | T22: 6.2564356 | U22: 2.847713 | V22: 2.6736147 | W22: =+Z24 -> 1.894 | X22: 45888 | Y22: May | Z22: 1.956 | AA22: 1,773-1,999 | AB22: 1.886 | AC22: -0.661 | AG22: Feb | AH22: 1.971 | AI22: 1.785-2.013 | AJ22: 1.899 | AK22: -0.227
A23: 202104 | B23: =+[1]Grafico_avec_FWL!AE14 -> 0.027355238 | C23: =B23 -> 0.027355238 | G23: =+[1]Grafico_avec_FWL!AD14 -> 0.039518039 | H23: =+gdp!D20 -> 4.6 | I23: -0.1 | J23: 7.1 | K23: 0.35 | L23: -0.5382 | M23: -0.4835 | P23: 2025-08 | R23: =+R24 -> 1.85 | S23: 2.3199071 | T23: 6.2564356 | U23: 2.847713 | V23: 2.6736147 | W23: =+Z25 -> 1.908 | X23: 2.126 | Y23: Jun | Z23: 1.886 | AA23: 1,780-2,008 | AB23: 1.894 | AC23: -0.653 | AG23: Mar | AH23: 1.899 | AI23: 1.697-1.913 | AJ23: 1.805 | AK23: -0.321
A24: 202105 | B24: =+[1]Grafico_avec_FWL!AE15 -> 0.023559645 | C24: =B24 -> 0.023559645 | G24: =+[1]Grafico_avec_FWL!AD15 -> 0.039518039 | H24: =+H23 -> 4.6 | I24: 0.5 | J24: 7.2 | K24: 0.53 | L24: -0.5401 | M24: -0.4806 | P24: 2025-09 | Q24: 2025-Q3 | R24: =+gdp!K37 -> 1.85 | S24: 2.3199071 | T24: 6.2564356 | U24: 2.847713 | V24: 2.6736147 | W24: =+Z26 -> 1.867 | X24: 2.056 | Y24: Jul | Z24: 1.894 | AA24: 1,794-2,022 | AB24: 1.908 | AC24: -0.639 | AG24: Apr | AH24: 1.805 | AI24: 1.685-1.901 | AJ24: 1.793 | AK24: -0.333
A25: 202106 | B25: =+[1]Grafico_avec_FWL!AE16 -> 0.023568045 | C25: =B25 -> 0.023568045 | G25: =+[1]Grafico_avec_FWL!AD16 -> 0.039518039 | H25: =+H24 -> 4.6 | I25: -0.6 | J25: 7 | K25: 0.43 | L25: -0.5429 | M25: -0.4839 | P25: 2025-10 | R25: =+R27 -> 1.78 | S25: 2.2181974 | T25: 6.2095872 | U25: 2.797713 | V25: 2.4236147 | W25: =+Z27 -> 1.844 | X25: 2.021 | Y25: Aug | Z25: 1.908 | AA25: 1,755-1,979 | AB25: 1.867 | AC25: -0.68 | AG25: May | AH25: 1.793 | AI25: 1.681-1.895 | AJ25: 1.788 | AK25: -0.338
A26: 202107 | B26: =+[1]Grafico_avec_FWL!AE17 -> 0.025690669 | C26: =B26 -> 0.025690669 | G26: =+[1]Grafico_avec_FWL!AD17 -> 0.039518039 | H26: =+gdp!D21 -> 3.6 | I26: 1.1 | J26: 6.7 | K26: 0.27 | L26: -0.5448 | M26: -0.4907 | P26: 2025-11 | R26: =+R27 -> 1.78 | S26: 2.2181974 | T26: 6.2095872 | U26: 2.797713 | V26: 2.4236147 | W26: =+Z28 -> 1.875 | X26: 2.074 | Y26: Sep | Z26: 1.867 | AA26: 1,733-1,955 | AB26: 1.844 | AC26: -0.703 | AG26: Jun | AH26: 1.788 | AI26: 1.624-1.832 | AJ26: 1.728 | AK26: -0.398
A27: 202108 | B27: =+[1]Grafico_avec_FWL!AE18 -> 0.025819417 | C27: =B27 -> 0.025819417 | G27: =+[1]Grafico_avec_FWL!AD18 -> 0.039518039 | H27: =+H26 -> 3.6 | I27: 1.3 | J27: 6.4 | K27: 0.14 | L27: -0.5476 | M27: -0.4982 | P27: 2025-12 | Q27: 2025-Q4 | R27: =+gdp!K38 -> 1.78 | S27: 2.2181974 | T27: 6.2095872 | U27: 2.797713 | V27: 2.4236147 | W27: =+Z29 -> 1.763 | X27: 2.056 | Y27: Oct | Z27: 1.844 | AA27: 1,763-1,988 | AB27: 1.875 | AC27: -0.672 | AG27: Jul | AH27: 1.728 | AI27: 1.527-1.728 | AJ27: 1.624 | AK27: -0.502
A28: 202109 | B28: =+[1]Grafico_avec_FWL!AE19 -> 0.02673671 | C28: =B28 -> 0.02673671 | G28: =+[1]Grafico_avec_FWL!AD19 -> 0.039518039 | H28: =+H27 -> 3.6 | I28: 1.3 | J28: 6.4 | K28: 0.26 | L28: -0.545 | M28: -0.4923 | P28: 2026-1 | R28: =+R30 -> 1.79 | T28: 6.4 | U28: =+Z31 -> 1.708 | W28: 2.097 | Y28: Nov | Z28: 1.875 | AA28: 1,657-1,875 | AB28: 1.763 | AC28: -0.784 | AG28: Aug | AH28: 1.624 | AI28: 1.435-1.624 | AJ28: 1.527 | AK28: -0.599
A29: 202110 | B29: =+[1]Grafico_avec_FWL!AE20 -> 0.02768909 | C29: =B29 -> 0.02768909 | G29: =+[1]Grafico_avec_FWL!AD20 -> 0.039518039 | H29: =+gdp!D22 -> 1.9 | I29: 1.8 | J29: 6.4 | K29: 0.39 | L29: -0.5498 | M29: -0.4768 | P29: 2026-2 | R29: =+R30 -> 1.79 | T29: =+$T$28 -> 6.4 | U29: =+Z32 -> 1.637 | W29: 1.971 | Y29: Dec | Z29: 1.763 | AA29: 1,606-1,810 | AB29: 1.708 | AC29: -0.839 | AG29: Sep | AH29: 1.527 | AI29: 1.349-1.527 | AJ29: 1.435 | AK29: -0.691
A30: 202111 | B30: =+[1]Grafico_avec_FWL!AE21 -> 0.028446148 | C30: =B30 -> 0.028446148 | G30: =+[1]Grafico_avec_FWL!AD21 -> 0.039518039 | H30: =+H29 -> 1.9 | I30: 2.6 | J30: 6.3 | K30: 0.39 | L30: -0.5674 | M30: -0.487 | P30: 2026-3 | Q30: 2026-Q1 | R30: =+gdp!K39 -> 1.79 | T30: =+$T$28 -> 6.4 | U30: =+Z33 -> 1.624 | W30: 1.899 | Y30: 2026 | AG30: Oct | AH30: 1.435 | AI30: 1.278-1.442 | AJ30: 1.36 | AK30: -0.766
A31: 202112 | B31: =+[1]Grafico_avec_FWL!AE22 -> 0.029269148 | C31: =B31 -> 0.029269148 | G31: =+[1]Grafico_avec_FWL!AD22 -> 0.039518039 | H31: =+H30 -> 1.9 | I31: 2.8 | J31: 6 | K31: 0.36 | L31: -0.582 | M31: -0.502 | P31: 2026-4 | R31: =+R32 -> 1.87 | T31: =+$T$28 -> 6.4 | U31: =+Z34 -> 1.639 | W31: 1.805 | Y31: Jan | Z31: 1.708 | AA31: 1,539-1,735 | AB31: 1.637 | AC31: -0.91 | AG31: Nov | AH31: 1.36 | AI31: 1.232-1.390 | AJ31: 1.311 | AK31: -0.815
A32: 202201 | B32: =+[1]Grafico_avec_FWL!AE23 -> 0.027318124 | C32: =B32 -> 0.027318124 | G32: =+[1]Grafico_avec_FWL!AD23 -> 0.039518039 | H32: =+gdp!D23 -> 1.7 | I32: 3.4 | J32: 5.9 | K32: 0.58 | L32: -0.5601 | M32: -0.4767 | P32: 2026-5 | R32: =+R33 -> 1.87 | T32: =+$T$28 -> 6.4 | U32: =+Z35 -> 1.611 | W32: 1.793 | Y32: Feb | Z32: 1.637 | AA32: 1,527-1,721 | AB32: 1.624 | AC32: -0.923 | AG32: Dec | AH32: 1.311 | AI32: 1.237-1.395 | AJ32: 1.316 | AK32: -0.81
A33: 202202 | B33: =+[1]Grafico_avec_FWL!AE24 -> 0.027578907 | C33: =B33 -> 0.027578907 | G33: =+[1]Grafico_avec_FWL!AD24 -> 0.039518039 | H33: =+H32 -> 1.7 | I33: 4.4 | J33: 5.8 | K33: 1.06 | L33: -0.5315 | M33: -0.3353 | P33: 2026-6 | Q33: 2026-Q2 | R33: =+gdp!K40 -> 1.87 | T33: =+$T$28 -> 6.4 | U33: =+Z36 -> 1.591 | W33: 1.788 | Y33: Mar | Z33: 1.624 | AA33: 1,541-1,737 | AB33: 1.639 | AC33: -0.908 | AG33: 2027
A34: 202203 | B34: =+[1]Grafico_avec_FWL!AE25 -> 0.028314984 | C34: =B34 -> 0.028314984 | G34: =+[1]Grafico_avec_FWL!AD25 -> 0.039518039 | H34: =+H33 -> 1.7 | I34: 5.5 | J34: 5.9 | K34: 1.16 | L34: -0.4954 | M34: -0.2374 | P34: 2026-7 | R34: =+R35 -> 1.95 | T34: =+$T$28 -> 6.4 | U34: =+Z37 -> 1.615 | W34: 1.728 | Y34: Apr | Z34: 1.639 | AA34: 1,514-1,708 | AB34: 1.611 | AC34: -0.936 | AG34: Jan | AH34: 1.316 | AI34: 1.246-1.406 | AJ34: 1.326 | AK34: -0.8
A35: 202204 | B35: =+[1]Grafico_avec_FWL!AE26 -> 0.032445719 | C35: =B35 -> 0.032445719 | G35: =+[1]Grafico_avec_FWL!AD26 -> 0.039518039 | H35: =+gdp!D24 -> 0.4 | I35: 7.4 | J35: 6 | K35: 1.76 | L35: -0.4479 | M35: 0.0131 | P35: 2026-8 | R35: =+R36 -> 1.95 | T35: =+$T$28 -> 6.4 | U35: =+Z38 -> 1.586 | W35: 1.624 | Y35: May | Z35: 1.611 | AA35: 1,496-1,686 | AB35: 1.591 | AC35: -0.956 | AG35: Feb | AH35: 1.326 | AI35: 1.220-1.376 | AJ35: 1.298 | AK35: -0.828
A36: 202205 | B36: =+[1]Grafico_avec_FWL!AE27 -> 0.033679873 | C36: =B36 -> 0.033679873 | G36: =+[1]Grafico_avec_FWL!AD27 -> 0.039518039 | H36: =+H35 -> 0.4 | I36: 8.1 | J36: 6.2 | K36: 2.14 | L36: -0.3857 | M36: 0.2866 | P36: 2026-9 | Q36: 2026-Q3 | R36: =+gdp!K41 -> 1.95 | T36: =+$T$28 -> 6.4 | U36: =+Z39 -> 1.542 | W36: 1.527 | Y36: Jun | Z36: 1.591 | AA36: 1,518-1,712 | AB36: 1.615 | AC36: -0.932 | AG36: Mar | AH36: 1.298 | AI36: 1.205-1.359 | AJ36: 1.282 | AK36: -0.844
A37: 202206 | B37: =+[1]Grafico_avec_FWL!AE28 -> 0.035237068 | C37: =B37 -> 0.035237068 | G37: =+[1]Grafico_avec_FWL!AD28 -> 0.039518039 | H37: =+H36 -> 0.4 | I37: 9 | J37: 6.1 | K37: 2.65 | L37: -0.2392 | M37: 0.8522 | P37: 2026-10 | R37: =+R39 -> 1.97 | T37: =+$T$28 -> 6.4 | U37: =+Z40 -> 1.507 | W37: 1.435 | Y37: Jul | Z37: 1.615 | AA37: 1,491-1,681 | AB37: 1.586 | AC37: -0.961 | AG37: Apr | AH37: 1.282 | AI37: 1.226-1.382 | AJ37: 1.304 | AK37: -0.822
A38: 202207 | B38: =+[1]Grafico_avec_FWL!AE29 -> 0.036317406 | C38: =B38 -> 0.036317406 | G38: =+[1]Grafico_avec_FWL!AD29 -> 0.039518039 | H38: =+gdp!D25 -> 1 | I38: 9.4 | J38: 6.2 | K38: 2.26 | L38: 0.0366 | M38: 0.9915 | P38: 2026-11 | R38: =+R39 -> 1.97 | T38: =+$T$28 -> 6.4 | U38: =+Z41 -> 1.493 | W38: 1.36 | Y38: Aug | Z38: 1.586 | AA38: 1,449-1,635 | AB38: 1.542 | AC38: -1.005 | AG38: May | AH38: 1.304 | AI38: 1.152-1.304 | AJ38: 1.226 | AK38: -0.9
A39: 202208 | B39: =+[1]Grafico_avec_FWL!AE30 -> 0.041386622 | C39: =B39 -> 0.041386622 | G39: =+[1]Grafico_avec_FWL!AD30 -> 0.039518039 | H39: =+H38 -> 1 | I39: 9.3 | J39: 6.2 | K39: 2.16 | L39: 0.3947 | M39: 1.2495 | P39: 2026-12 | Q39: 2026-Q4 | R39: =+gdp!K42 -> 1.97 | T39: =+$T$28 -> 6.4 | W39: 1.311 | Y39: Sep | Z39: 1.542 | AA39: 1,417-1,597 | AB39: 1.507 | AC39: -1.04 | AG39: Jun | AH39: 1.226 | AI39: 1.117-1.259 | AJ39: 1.188 | AK39: -0.938
A40: 202209 | B40: =+[1]Grafico_avec_FWL!AE31 -> 0.042502618 | C40: =B40 -> 0.042502618 | G40: =+[1]Grafico_avec_FWL!AD31 -> 0.039518039 | H40: =+H39 -> 1 | I40: 9.8 | J40: 6.2 | K40: 2.89 | L40: 1.0109 | M40: 2.233 | Y40: Oct | Z40: 1.507 | AA40: 1,403-1,583 | AB40: 1.493 | AC40: -1.054 | AG40: Jul | AH40: 1.188 | AI40: 1.071-1.207 | AJ40: 1.139 | AK40: -0.987
...

Sheet Consolidado_projection
C2: Parâmetros | P2: Linear Regression Results
C3: =+P20 -> Intercept | D3: =+P21 -> Unemployment_Rate | E3: =+P22 -> GDP_9 | F3: =+P23 -> Inflation_11 | G3: =+P24 -> LT_Interest_Rate_6 | H3: =+P25 -> LT_Interest_Rate_8 | P3: The REG Procedure
C4: =+Consolidado_projection!R20 -> 0.00481 | D4: =+R21 -> 0.0029 | E4: =+R22 -> -0.00027269 | F4: =+R23 -> 0.00204 | G4: =+R24 -> 0.0043 | H4: =+R25 -> 0.00426 | P4: Model: Linear_Regression_Model
B5: Efeito TD12M_Autopor | D5: =+IF(D4>0,"↑","↓") -> ↑ | E5: =+IF(E4>0,"↑","↓") -> ↓ | F5: =+IF(F4>0,"↑","↓") -> ↑ | G5: =+IF(G4>0,"↑","↓") -> ↑ | H5: =+IF(H4>0,"↑","↓") -> ↑ | P5: Dependent Variable: TD_12M_Consolidado
P6: Number of Observations Read | Q6: 49
B7: Backtesting | P7: Number of Observations Used | Q7: 49 | Z7: link of explanation
P8: Analysis of Variance | Z8: Ithy - Comprendre les Métriques de Régression : MAE, MSE, RMSE et R²
J9: CONSOLIDADO | P9: Source | Q9: DF | R9: Sum of | S9: Mean | T9: F Value | U9: Pr > F
B10: t | C10: intercept | D10: =+D3 -> Unemployment_Rate | E10: =+E3 -> GDP_9 | F10: =+F3 -> Inflation_11 | G10: =+G3 -> LT_Interest_Rate_6 | H10: =+H3 -> LT_Interest_Rate_8 | J10: TD12M estimated | L10: TD12M observed (real) | R10: Squares | S10: Square | Z10: t | AA10: TD12M estimated | AC10: TD12M observed (real) | AE10: Difference | AG10: power 2 | AI10: Sum | AK10: MSE | AM10: RMSE
B11: =+Portugal_indicadores!A63 -> 202408 | D11: =+Portugal_indicadores!J63 -> 6.1 | E11: =+Portugal_indicadores!H54 -> 0.6 | F11: =+Portugal_indicadores!I52 -> 4.8 | G11: =+Portugal_indicadores!K57 -> 3.06 | H11: =+Portugal_indicadores!K55 -> 2.85 | J11: =+$C$4+D11*$D$4+E11*$E$4+F11*$F$4+$H$4*H11+$G$4*G11 -> 0.057427386 | L11: =+Portugal_indicadores!G63 -> 0.075658259 | N11: =+L11-J11 -> 0.018230873 | P11: Model | Q11: 5 | R11: 0.01677 | S11: 0.00335 | T11: 572.49 | U11: <,0001 | Z11: =+B11 -> 202408 | AA11: =J11 -> 0.057427386 | AC11: =L11 -> 0.075658259 | AE11: =AC11-AA11 -> 0.018230873 | AG11: =POWER(AE11,2) -> 0.00033236474 | AI11: =SUM(AG11:AG22) -> 0.0057018339 | AK11: =(1/COUNT(Z11:Z22))*AI11 -> 0.00047515282 | AM11: =SQRT(AK11) -> 0.021798
B12: =+Portugal_indicadores!A64 -> 202409 | D12: =+Portugal_indicadores!J64 -> 6.1 | E12: =+Portugal_indicadores!H55 -> 0.6 | F12: =+Portugal_indicadores!I53 -> 3.2 | G12: =+Portugal_indicadores!K58 -> 3.02 | H12: =+Portugal_indicadores!K56 -> 2.97 | J12: =+$C$4+D12*$D$4+E12*$E$4+F12*$F$4+$H$4*H12+$G$4*G12 -> 0.054502586 | L12: =+Portugal_indicadores!G64 -> 0.075658259 | N12: =+L12-J12 -> 0.021155673 | P12: Error | Q12: 43 | R12: 0.00025198 | S12: 5.86e-06 | Z12: =+B12 -> 202409 | AA12: =J12 -> 0.054502586 | AC12: =L12 -> 0.075658259 | AE12: =AC12-AA12 -> 0.021155673 | AG12: =POWER(AE12,2) -> 0.00044756252
B13: =+Portugal_indicadores!A65 -> 202410 | D13: =+Portugal_indicadores!J65 -> 6.7 | E13: =+Portugal_indicadores!H56 -> 0.6 | F13: =+Portugal_indicadores!I54 -> 2.2 | G13: =+Portugal_indicadores!K59 -> 3.13 | H13: =+Portugal_indicadores!K57 -> 3.06 | J13: =+$C$4+D13*$D$4+E13*$E$4+F13*$F$4+$H$4*H13+$G$4*G13 -> 0.055058986 | L13: =+Portugal_indicadores!G65 -> 0.075658259 | N13: =+L13-J13 -> 0.020599273 | P13: Corrected Total | Q13: 48 | R13: 0.01703 | Z13: =+B13 -> 202410 | AA13: =J13 -> 0.055058986 | AC13: =L13 -> 0.075658259 | AE13: =AC13-AA13 -> 0.020599273 | AG13: =POWER(AE13,2) -> 0.00042433006
B14: =+Portugal_indicadores!A66 -> 202411 | D14: =+Portugal_indicadores!J66 -> 6.7 | E14: =+Portugal_indicadores!H57 -> 0.6 | F14: =+Portugal_indicadores!I55 -> 1.9 | G14: =+Portugal_indicadores!K60 -> 3.16 | H14: =+Portugal_indicadores!K58 -> 3.02 | J14: =+$C$4+D14*$D$4+E14*$E$4+F14*$F$4+$H$4*H14+$G$4*G14 -> 0.054405586 | L14: =+Portugal_indicadores!G66 -> 0.075658259 | N14: =+L14-J14 -> 0.021252673 | P14: Root MSE | Q14: 0.00242 | R14: R-Square | S14: 0.9852 | Z14: =+B14 -> 202411 | AA14: =J14 -> 0.054405586 | AC14: =L14 -> 0.075658259 | AE14: =AC14-AA14 -> 0.021252673 | AG14: =POWER(AE14,2) -> 0.00045167613 | AM14: =AM11/AC14 -> 0.28811131
B15: =+Portugal_indicadores!A67 -> 202412 | D15: =+Portugal_indicadores!J67 -> 6.7 | E15: =+Portugal_indicadores!H58 -> 0.6 | F15: =+Portugal_indicadores!I56 -> 2.5 | G15: =+Portugal_indicadores!K61 -> 3.19 | H15: =+Portugal_indicadores!K59 -> 3.13 | J15: =+$C$4+D15*$D$4+E15*$E$4+F15*$F$4+$H$4*H15+$G$4*G15 -> 0.056227186 | L15: =+Portugal_indicadores!G67 -> 0.075658259 | N15: =+L15-J15 -> 0.019431073 | P15: Dependent Mean | Q15: 0.04336 | R15: Adj R-Sq | S15: 0.9835 | Z15: =+B15 -> 202412 | AA15: =J15 -> 0.056227186 | AC15: =L15 -> 0.075658259 | AE15: =AC15-AA15 -> 0.019431073 | AG15: =POWER(AE15,2) -> 0.00037756661
B16: =+Portugal_indicadores!A68 -> 202501 | D16: =+Portugal_indicadores!J68 -> 6.6 | E16: =+Portugal_indicadores!H59 -> 0.4 | F16: =+Portugal_indicadores!I57 -> 2.3 | G16: =+Portugal_indicadores!K62 -> 3.1 | H16: =+Portugal_indicadores!K60 -> 3.16 | J16: =+$C$4+D16*$D$4+E16*$E$4+F16*$F$4+$H$4*H16+$G$4*G16 -> 0.055324524 | L16: =+Portugal_indicadores!G68 -> 0.075658259 | N16: =+L16-J16 -> 0.020333735 | P16: Coeff Var | Q16: 5.58298 | Z16: =+B16 -> 202501 | AA16: =J16 -> 0.055324524 | AC16: =L16 -> 0.075658259 | AE16: =AC16-AA16 -> 0.020333735 | AG16: =POWER(AE16,2) -> 0.00041346079
B17: =+Portugal_indicadores!A69 -> 202502 | D17: =+Portugal_indicadores!J69 -> 6.6 | E17: =+Portugal_indicadores!H60 -> 0.4 | F17: =+Portugal_indicadores!I58 -> 2.6 | G17: =+Portugal_indicadores!K63 -> 2.88 | H17: =+Portugal_indicadores!K61 -> 3.19 | J17: =+$C$4+D17*$D$4+E17*$E$4+F17*$F$4+$H$4*H17+$G$4*G17 -> 0.055118324 | L17: =+Portugal_indicadores!G69 -> 0.075658259 | N17: =+L17-J17 -> 0.020539935 | P17: Parameter Estimates | Z17: =+B17 -> 202502 | AA17: =J17 -> 0.055118324 | AC17: =L17 -> 0.075658259 | AE17: =AC17-AA17 -> 0.020539935 | AG17: =POWER(AE17,2) -> 0.00042188895
B18: =+Portugal_indicadores!A70 -> 202503 | D18: =+Portugal_indicadores!J70 -> 6.6 | E18: =+Portugal_indicadores!H61 -> 0.4 | F18: =+Portugal_indicadores!I59 -> 2.3 | G18: =+Portugal_indicadores!K64 -> 2.78 | H18: =+Portugal_indicadores!K62 -> 3.1 | J18: =+$C$4+D18*$D$4+E18*$E$4+F18*$F$4+$H$4*H18+$G$4*G18 -> 0.053692924 | L18: =+Portugal_indicadores!G70 -> 0.075658259 | N18: =+L18-J18 -> 0.021965335 | P18: Variable | Q18: DF | R18: Parameter | S18: Standard | T18: t Value | U18: Pr > |t| | Z18: =+B18 -> 202503 | AA18: =J18 -> 0.053692924 | AC18: =L18 -> 0.075658259 | AE18: =AC18-AA18 -> 0.021965335 | AG18: =POWER(AE18,2) -> 0.00048247596
B19: =+Portugal_indicadores!A71 -> 202504 | D19: =+Portugal_indicadores!J71 -> 5.9 | E19: =+Portugal_indicadores!H62 -> 0.4 | F19: =+Portugal_indicadores!I60 -> 3.8 | G19: =+Portugal_indicadores!K65 -> 2.73 | H19: =+Portugal_indicadores!K63 -> 2.88 | J19: =+$C$4+D19*$D$4+E19*$E$4+F19*$F$4+$H$4*H19+$G$4*G19 -> 0.053570724 | L19: =+Portugal_indicadores!G71 -> 0.075658259 | N19: =+L19-J19 -> 0.022087535 | R19: Estimate | S19: Error | Z19: =+B19 -> 202504 | AA19: =J19 -> 0.053570724 | AC19: =L19 -> 0.075658259 | AE19: =AC19-AA19 -> 0.022087535 | AG19: =POWER(AE19,2) -> 0.00048785922
B20: =+Portugal_indicadores!A72 -> 202505 | D20: =+Portugal_indicadores!J72 -> 5.9 | E20: =+Portugal_indicadores!H63 -> 0.4 | F20: =+Portugal_indicadores!I61 -> 3.1 | G20: =+Portugal_indicadores!K66 -> 2.79 | H20: =+Portugal_indicadores!K64 -> 2.78 | J20: =+$C$4+D20*$D$4+E20*$E$4+F20*$F$4+$H$4*H20+$G$4*G20 -> 0.051974724 | L20: =+Portugal_indicadores!G72 -> 0.075658259 | N20: =+L20-J20 -> 0.023683535 | P20: Intercept | Q20: 1 | R20: 0.00481 | S20: 0.00424 | T20: 1.13 | U20: 0.2628 | Z20: =+B20 -> 202505 | AA20: =J20 -> 0.051974724 | AC20: =L20 -> 0.075658259 | AE20: =AC20-AA20 -> 0.023683535 | AG20: =POWER(AE20,2) -> 0.00056090985
B21: =+Portugal_indicadores!A73 -> 202506 | D21: =+Portugal_indicadores!J73 -> 5.9 | E21: =+Portugal_indicadores!H64 -> 0.4 | F21: =+Portugal_indicadores!I62 -> 2.7 | G21: =+Portugal_indicadores!K67 -> 2.68 | H21: =+Portugal_indicadores!K65 -> 2.73 | J21: =+$C$4+D21*$D$4+E21*$E$4+F21*$F$4+$H$4*H21+$G$4*G21 -> 0.050472724 | L21: =+Portugal_indicadores!G73 -> 0.075658259 | N21: =+L21-J21 -> 0.025185535 | P21: Unemployment_Rate | Q21: 1 | R21: 0.0029 | S21: 0.00062163 | T21: 4.67 | U21: <,0001 | Z21: =+B21 -> 202506 | AA21: =J21 -> 0.050472724 | AC21: =L21 -> 0.075658259 | AE21: =AC21-AA21 -> 0.025185535 | AG21: =POWER(AE21,2) -> 0.00063431119
B22: =+Portugal_indicadores!A74 -> 202507 | D22: =+Portugal_indicadores!J74 -> 5.9 | E22: =+Portugal_indicadores!H65 -> 1.4 | F22: =+Portugal_indicadores!I63 -> 1.8 | G22: =+Portugal_indicadores!K68 -> 2.96 | H22: =+Portugal_indicadores!K66 -> 2.79 | J22: =+$C$4+D22*$D$4+E22*$E$4+F22*$F$4+$H$4*H22+$G$4*G22 -> 0.049823634 | L22: =+Portugal_indicadores!G74 -> 0.075658259 | N22: =+L22-J22 -> 0.025834625 | P22: GDP_9 | Q22: 1 | R22: -0.00027269 | S22: 6.347e-05 | T22: -4.3 | U22: <,0001 | Z22: =+B22 -> 202507 | AA22: =J22 -> 0.049823634 | AC22: =L22 -> 0.075658259 | AE22: =AC22-AA22 -> 0.025834625 | AG22: =POWER(AE22,2) -> 0.00066742787
J23: =+AVERAGE(J11:J22) -> 0.053966609 | L23: =+AVERAGE(L11:L22) -> 0.075658259 | N23: =+L23-J23 -> 0.02169165 | P23: Inflation_11 | Q23: 1 | R23: 0.00204 | S23: 0.00026142 | T23: 7.79 | U23: <,0001
P24: LT_Interest_Rate_6 | Q24: 1 | R24: 0.0043 | S24: 0.00103 | T24: 4.16 | U24: 0.0001
P25: LT_Interest_Rate_8 | Q25: 1 | R25: 0.00426 | S25: 0.00096012 | T25: 4.44 | U25: <,0001
B26: Baseline Projection | P26: Correlation of Estimates
D27: =+D4 -> 0.0029 | E27: =+E4 -> -0.00027269 | F27: =+F4 -> 0.00204 | G27: =+G4 -> 0.0043 | H27: =+H4 -> 0.00426 | P27: Variable | Q27: Intercept | R27: Unemployment_Rate | S27: GDP_9 | T27: Inflation_11 | U27: LT_Interest_Rate_6 | V27: LT_Interest_Rate_8
B28: t | C28: intercept | D28: =+D10 -> Unemployment_Rate | E28: =+E10 -> GDP_9 | F28: =+F10 -> Inflation_11 | G28: =+G10 -> LT_Interest_Rate_6 | H28: =+H10 -> LT_Interest_Rate_8 | J28: TD12M Projected | P28: Intercept | Q28: 1 | R28: -0.9901 | S28: -0.1153 | T28: 0.0914 | U28: -0.1105 | V28: -0.0218
B29: =+Portugal_indicadores!A75 -> 202508 | D29: =+Portugal_indicadores!T23 -> 6.2564356 | E29: =+Portugal_indicadores!R14 -> 1.4 | F29: =+Portugal_indicadores!S12 -> 2.6 | G29: =+Portugal_indicadores!U17 -> 2.917713 | H29: =+Portugal_indicadores!U15 -> 2.937713 | J29: =+$C$4+D29*$D$4+E29*$E$4+F29*$F$4+$H$4*H29+G29*$G$4 -> 0.05293672 | P29: Unemployment_Rate | Q29: -0.9901 | R29: 1 | S29: 0.0989 | T29: -0.0316 | U29: 0.0545 | V29: 0.0113
B30: =+Portugal_indicadores!A76 -> 202509 | D30: =+Portugal_indicadores!T24 -> 6.2564356 | E30: =+Portugal_indicadores!R15 -> 1.4 | F30: =+Portugal_indicadores!S13 -> 2.6 | G30: =+Portugal_indicadores!U18 -> 2.917713 | H30: =+Portugal_indicadores!U16 -> 2.917713 | J30: =+$C$4+D30*$D$4+E30*$E$4+F30*$F$4+$H$4*H30+G30*$G$4 -> 0.05285152 | P30: GDP_9 | Q30: -0.1153 | R30: 0.0989 | S30: 1 | T30: -0.1252 | U30: 0.0413 | V30: 0.0621
B31: =+Portugal_indicadores!A77 -> 202510 | D31: =+Portugal_indicadores!T25 -> 6.2095872 | E31: =+Portugal_indicadores!R16 -> -0.4 | F31: =+Portugal_indicadores!S14 -> 3.0129637 | G31: =+Portugal_indicadores!U19 -> 2.887713 | H31: =+Portugal_indicadores!U17 -> 2.917713 | J31: =+$C$4+D31*$D$4+E31*$E$4+F31*$F$4+$H$4*H31+G31*$G$4 -> 0.053919948 | P31: Inflation_11 | Q31: 0.0914 | R31: -0.0316 | S31: -0.1252 | T31: 1 | U31: -0.455 | V31: -0.2624
B32: =+Portugal_indicadores!A78 -> 202511 | D32: =+Portugal_indicadores!T26 -> 6.2095872 | E32: =+Portugal_indicadores!R17 -> -0.4 | F32: =+Portugal_indicadores!S15 -> 3.0129637 | G32: =+Portugal_indicadores!U20 -> 2.887713 | H32: =+Portugal_indicadores!U18 -> 2.917713 | J32: =+$C$4+D32*$D$4+E32*$E$4+F32*$F$4+$H$4*H32+G32*$G$4 -> 0.053919948 | P32: LT_Interest_Rate_6 | Q32: -0.1105 | R32: 0.0545 | S32: 0.0413 | T32: -0.455 | U32: 1 | V32: -0.7031
B33: =+Portugal_indicadores!A79 -> 202512 | D33: =+Portugal_indicadores!T27 -> 6.2095872 | E33: =+Portugal_indicadores!R18 -> -0.4 | F33: =+Portugal_indicadores!S16 -> 2.5845929 | G33: =+Portugal_indicadores!U21 -> 2.887713 | H33: =+Portugal_indicadores!U19 -> 2.887713 | J33: =+$C$4+D33*$D$4+E33*$E$4+F33*$F$4+$H$4*H33+G33*$G$4 -> 0.052918271 | P33: LT_Interest_Rate_8 | Q33: -0.0218 | R33: 0.0113 | S33: 0.0621 | T33: -0.2624 | U33: -0.7031 | V33: 1
B34: =+Portugal_indicadores!A80 -> 202601 | D34: =+Portugal_indicadores!T28 -> 6.4 | E34: =+Portugal_indicadores!R19 -> 0.6 | F34: =+Portugal_indicadores!S17 -> 2.5845929 | G34: =+Portugal_indicadores!U22 -> 2.847713 | H34: =+Portugal_indicadores!U20 -> 2.887713 | J34: =+$C$4+D34*$D$4+E34*$E$4+F34*$F$4+$H$4*H34+G34*$G$4 -> 0.053025778 | P34: Generated by the SAS System ('SASMain', X64_SRV19) on August 29, 2025 at 12:54:30 AM
B35: =+Portugal_indicadores!A81 -> 202602 | D35: =+Portugal_indicadores!T29 -> 6.4 | E35: =+Portugal_indicadores!R20 -> 0.6 | F35: =+Portugal_indicadores!S18 -> 2.5845929 | G35: =+Portugal_indicadores!U23 -> 2.847713 | H35: =+Portugal_indicadores!U21 -> 2.887713 | J35: =+$C$4+D35*$D$4+E35*$E$4+F35*$F$4+$H$4*H35+G35*$G$4 -> 0.053025778
B36: =+Portugal_indicadores!A82 -> 202603 | D36: =+Portugal_indicadores!T30 -> 6.4 | E36: =+Portugal_indicadores!R21 -> 0.6 | F36: =+Portugal_indicadores!S19 -> 2.4013153 | G36: =+Portugal_indicadores!U24 -> 2.847713 | H36: =+Portugal_indicadores!U22 -> 2.847713 | J36: =+$C$4+D36*$D$4+E36*$E$4+F36*$F$4+$H$4*H36+G36*$G$4 -> 0.052481492 | P36: Linear Regression Results
B37: =+Portugal_indicadores!A83 -> 202604 | D37: =+Portugal_indicadores!T31 -> 6.4 | E37: =+Portugal_indicadores!R22 -> 1.85 | F37: =+Portugal_indicadores!S20 -> 2.4013153 | G37: =+Portugal_indicadores!U25 -> 2.797713 | H37: =+Portugal_indicadores!U23 -> 2.847713 | J37: =+$C$4+D37*$D$4+E37*$E$4+F37*$F$4+$H$4*H37+G37*$G$4 -> 0.05192563 | P37: The REG Procedure
B38: =+Portugal_indicadores!A84 -> 202605 | D38: =+Portugal_indicadores!T32 -> 6.4 | E38: =+Portugal_indicadores!R23 -> 1.85 | F38: =+Portugal_indicadores!S21 -> 2.4013153 | G38: =+Portugal_indicadores!U26 -> 2.797713 | H38: =+Portugal_indicadores!U24 -> 2.847713 | J38: =+$C$4+D38*$D$4+E38*$E$4+F38*$F$4+$H$4*H38+G38*$G$4 -> 0.05192563 | P38: Model: Linear_Regression_Model
B39: =+Portugal_indicadores!A85 -> 202606 | D39: =+Portugal_indicadores!T33 -> 6.4 | E39: =+Portugal_indicadores!R24 -> 1.85 | F39: =+Portugal_indicadores!S22 -> 2.3199071 | G39: =+Portugal_indicadores!U27 -> 2.797713 | H39: =+Portugal_indicadores!U25 -> 2.797713 | J39: =+$C$4+D39*$D$4+E39*$E$4+F39*$F$4+$H$4*H39+G39*$G$4 -> 0.051546557 | P39: Dependent Variable: TD_12M_Consolidado
B40: =+Portugal_indicadores!A86 -> 202607 | D40: =+Portugal_indicadores!T34 -> 6.4 | E40: =+Portugal_indicadores!R25 -> 1.78 | F40: =+Portugal_indicadores!S23 -> 2.3199071 | G40: =+Portugal_indicadores!U28 -> 1.708 | H40: =+Portugal_indicadores!U26 -> 2.797713 | J40: =+$C$4+D40*$D$4+E40*$E$4+F40*$F$4+$H$4*H40+G40*$G$4 -> 0.04687988 | P40: Test of First and Second
B41: =+Portugal_indicadores!A87 -> 202608 | D41: =+Portugal_indicadores!T35 -> 6.4 | E41: =+Portugal_indicadores!R26 -> 1.78 | F41: =+Portugal_indicadores!S24 -> 2.3199071 | G41: =+Portugal_indicadores!U29 -> 1.637 | H41: =+Portugal_indicadores!U27 -> 2.797713 | J41: =+$C$4+D41*$D$4+E41*$E$4+F41*$F$4+$H$4*H41+G41*$G$4 -> 0.04657458 | P41: Moment Specification
...

Sheet Consolidado_projection (2)
C2: Parâmetros | N2: Linear Regression Results
C3: =+N20 -> Intercept | D3: =+N21 -> Unemployment_Rate | E3: =+N22 -> GDP_9 | F3: =+N23 -> Euribor1year_3 | N3: The REG Procedure
C4: =+'Consolidado_projection (2)'!P20 -> 0.01491 | D4: =+P21 -> 0.00241 | E4: =+P22 -> -0.00039175 | F4: =+P23 -> 0.00951 | N4: Model: Linear_Regression_Model
B5: Efeito TD12M_Autopor | D5: =+IF(D4>0,"↑","↓") -> ↑ | E5: =+IF(E4>0,"↑","↓") -> ↓ | F5: =+IF(F4>0,"↑","↓") -> ↑ | N5: Dependent Variable: TD_12M_Consolidado
N6: Number of Observations Read | O6: 49
B7: Backtesting | N7: Number of Observations Used | O7: 49
N8: Analysis of Variance
H9: CONSOLIDADO | N9: Source | O9: DF | P9: Sum of | Q9: Mean | R9: F Value | S9: Pr > F
B10: t | C10: intercept | D10: =+D3 -> Unemployment_Rate | E10: =+E3 -> GDP_9 | F10: =+F3 -> Euribor1year_3 | H10: TD12M estimated | J10: TD12M observed (real) | P10: Squares | Q10: Square | X10: t | Y10: TD12M estimated | AA10: TD12M observed (real) | AC10: Difference | AE10: power 2 | AG10: Sum | AI10: MSE | AK10: RMSE
B11: =+Portugal_indicadores!A63 -> 202408 | D11: =+Portugal_indicadores!J63 -> 6.1 | E11: =+Portugal_indicadores!H54 -> 0.6 | F11: =+Portugal_indicadores!M60 -> 3.6821 | H11: =+$C$4+D11*$D$4+E11*$E$4+F11*$F$4 -> 0.064392721 | J11: =+Portugal_indicadores!G63 -> 0.075658259 | L11: =+J11-H11 -> 0.011265538 | N11: Model | O11: 3 | P11: 0.01647 | Q11: 0.00549 | R11: 440.59 | S11: <,0001 | X11: =B11 -> 202408 | Y11: =H11 -> 0.064392721 | AA11: =J11 -> 0.075658259 | AC11: =AA11-Y11 -> 0.011265538 | AE11: =POWER(AC11,2) -> 0.00012691236 | AG11: =SUM(AE11:AE22) -> 0.0045482283 | AI11: =(1/COUNT(X11:X22))*AG11 -> 0.00037901902 | AK11: =SQRT(AI11) -> 0.019468411
B12: =+Portugal_indicadores!A64 -> 202409 | D12: =+Portugal_indicadores!J64 -> 6.1 | E12: =+Portugal_indicadores!H55 -> 0.6 | F12: =+Portugal_indicadores!M61 -> 3.6496 | H12: =+$C$4+D12*$D$4+E12*$E$4+F12*$F$4 -> 0.064083646 | J12: =+Portugal_indicadores!G64 -> 0.075658259 | L12: =+J12-H12 -> 0.011574613 | N12: Error | O12: 45 | P12: 0.00056057 | Q12: 1.246e-05 | X12: =B12 -> 202409 | Y12: =H12 -> 0.064083646 | AA12: =J12 -> 0.075658259 | AC12: =AA12-Y12 -> 0.011574613 | AE12: =POWER(AC12,2) -> 0.00013397168
B13: =+Portugal_indicadores!A65 -> 202410 | D13: =+Portugal_indicadores!J65 -> 6.7 | E13: =+Portugal_indicadores!H56 -> 0.6 | F13: =+Portugal_indicadores!M62 -> 3.5259 | H13: =+$C$4+D13*$D$4+E13*$E$4+F13*$F$4 -> 0.064353259 | J13: =+Portugal_indicadores!G65 -> 0.075658259 | L13: =+J13-H13 -> 0.011305 | N13: Corrected Total | O13: 48 | P13: 0.01703 | X13: =B13 -> 202410 | Y13: =H13 -> 0.064353259 | AA13: =J13 -> 0.075658259 | AC13: =AA13-Y13 -> 0.011305 | AE13: =POWER(AC13,2) -> 0.00012780303
B14: =+Portugal_indicadores!A66 -> 202411 | D14: =+Portugal_indicadores!J66 -> 6.7 | E14: =+Portugal_indicadores!H57 -> 0.6 | F14: =+Portugal_indicadores!M63 -> 3.17 | H14: =+$C$4+D14*$D$4+E14*$E$4+F14*$F$4 -> 0.06096865 | J14: =+Portugal_indicadores!G66 -> 0.075658259 | L14: =+J14-H14 -> 0.014689609 | N14: Root MSE | O14: 0.00353 | P14: R-Square | Q14: 0.9671 | X14: =B14 -> 202411 | Y14: =H14 -> 0.06096865 | AA14: =J14 -> 0.075658259 | AC14: =AA14-Y14 -> 0.014689609 | AE14: =POWER(AC14,2) -> 0.00021578462
B15: =+Portugal_indicadores!A67 -> 202412 | D15: =+Portugal_indicadores!J67 -> 6.7 | E15: =+Portugal_indicadores!H58 -> 0.6 | F15: =+Portugal_indicadores!M64 -> 2.94 | H15: =+$C$4+D15*$D$4+E15*$E$4+F15*$F$4 -> 0.05878135 | J15: =+Portugal_indicadores!G67 -> 0.075658259 | L15: =+J15-H15 -> 0.016876909 | N15: Dependent Mean | O15: 0.04336 | P15: Adj R-Sq | Q15: 0.9649 | X15: =B15 -> 202412 | Y15: =H15 -> 0.05878135 | AA15: =J15 -> 0.075658259 | AC15: =AA15-Y15 -> 0.016876909 | AE15: =POWER(AC15,2) -> 0.00028483007
B16: =+Portugal_indicadores!A68 -> 202501 | D16: =+Portugal_indicadores!J68 -> 6.6 | E16: =+Portugal_indicadores!H59 -> 0.4 | F16: =+Portugal_indicadores!M65 -> 2.69 | H16: =+$C$4+D16*$D$4+E16*$E$4+F16*$F$4 -> 0.0562412 | J16: =+Portugal_indicadores!G68 -> 0.075658259 | L16: =+J16-H16 -> 0.019417059 | N16: Coeff Var | O16: 8.14008 | X16: =B16 -> 202501 | Y16: =H16 -> 0.0562412 | AA16: =J16 -> 0.075658259 | AC16: =AA16-Y16 -> 0.019417059 | AE16: =POWER(AC16,2) -> 0.0003770222
B17: =+Portugal_indicadores!A69 -> 202502 | D17: =+Portugal_indicadores!J69 -> 6.6 | E17: =+Portugal_indicadores!H60 -> 0.4 | F17: =+Portugal_indicadores!M66 -> 2.51 | H17: =+$C$4+D17*$D$4+E17*$E$4+F17*$F$4 -> 0.0545294 | J17: =+Portugal_indicadores!G69 -> 0.075658259 | L17: =+J17-H17 -> 0.021128859 | N17: Parameter Estimates | X17: =B17 -> 202502 | Y17: =H17 -> 0.0545294 | AA17: =J17 -> 0.075658259 | AC17: =AA17-Y17 -> 0.021128859 | AE17: =POWER(AC17,2) -> 0.0004464287
B18: =+Portugal_indicadores!A70 -> 202503 | D18: =+Portugal_indicadores!J70 -> 6.6 | E18: =+Portugal_indicadores!H61 -> 0.4 | F18: =+Portugal_indicadores!M67 -> 2.44 | H18: =+$C$4+D18*$D$4+E18*$E$4+F18*$F$4 -> 0.0538637 | J18: =+Portugal_indicadores!G70 -> 0.075658259 | L18: =+J18-H18 -> 0.021794559 | N18: Variable | O18: DF | P18: Parameter | Q18: Standard | R18: t Value | S18: Pr > |t| | X18: =B18 -> 202503 | Y18: =H18 -> 0.0538637 | AA18: =J18 -> 0.075658259 | AC18: =AA18-Y18 -> 0.021794559 | AE18: =POWER(AC18,2) -> 0.00047500282
B19: =+Portugal_indicadores!A71 -> 202504 | D19: =+Portugal_indicadores!J71 -> 5.9 | E19: =+Portugal_indicadores!H62 -> 0.4 | F19: =+Portugal_indicadores!M68 -> 2.53 | H19: =+$C$4+D19*$D$4+E19*$E$4+F19*$F$4 -> 0.0530326 | J19: =+Portugal_indicadores!G71 -> 0.075658259 | L19: =+J19-H19 -> 0.022625659 | P19: Estimate | Q19: Error | X19: =B19 -> 202504 | Y19: =H19 -> 0.0530326 | AA19: =J19 -> 0.075658259 | AC19: =AA19-Y19 -> 0.022625659 | AE19: =POWER(AC19,2) -> 0.00051192046
B20: =+Portugal_indicadores!A72 -> 202505 | D20: =+Portugal_indicadores!J72 -> 5.9 | E20: =+Portugal_indicadores!H63 -> 0.4 | F20: =+Portugal_indicadores!M69 -> 2.41 | H20: =+$C$4+D20*$D$4+E20*$E$4+F20*$F$4 -> 0.0518914 | J20: =+Portugal_indicadores!G72 -> 0.075658259 | L20: =+J20-H20 -> 0.023766859 | N20: Intercept | O20: 1 | P20: 0.01491 | Q20: 0.00606 | R20: 2.46 | S20: 0.0179 | X20: =B20 -> 202505 | Y20: =H20 -> 0.0518914 | AA20: =J20 -> 0.075658259 | AC20: =AA20-Y20 -> 0.023766859 | AE20: =POWER(AC20,2) -> 0.00056486361
B21: =+Portugal_indicadores!A73 -> 202506 | D21: =+Portugal_indicadores!J73 -> 5.9 | E21: =+Portugal_indicadores!H64 -> 0.4 | F21: =+Portugal_indicadores!M70 -> 2.4 | H21: =+$C$4+D21*$D$4+E21*$E$4+F21*$F$4 -> 0.0517963 | J21: =+Portugal_indicadores!G73 -> 0.075658259 | L21: =+J21-H21 -> 0.023861959 | N21: Unemployment_Rate | O21: 1 | P21: 0.00241 | Q21: 0.00090296 | R21: 2.67 | S21: 0.0105 | X21: =B21 -> 202506 | Y21: =H21 -> 0.0517963 | AA21: =J21 -> 0.075658259 | AC21: =AA21-Y21 -> 0.023861959 | AE21: =POWER(AC21,2) -> 0.00056939311
B22: =+Portugal_indicadores!A74 -> 202507 | D22: =+Portugal_indicadores!J74 -> 5.9 | E22: =+Portugal_indicadores!H65 -> 1.4 | F22: =+Portugal_indicadores!M71 -> 2.14 | H22: =+$C$4+D22*$D$4+E22*$E$4+F22*$F$4 -> 0.04893195 | J22: =+Portugal_indicadores!G74 -> 0.075658259 | L22: =+J22-H22 -> 0.026726309 | N22: GDP_9 | O22: 1 | P22: -0.00039175 | Q22: 9.17e-05 | R22: -4.27 | S22: <,0001 | X22: =B22 -> 202507 | Y22: =H22 -> 0.04893195 | AA22: =J22 -> 0.075658259 | AC22: =AA22-Y22 -> 0.026726309 | AE22: =POWER(AC22,2) -> 0.00071429561
H23: =+AVERAGE(H11:H22) -> 0.056905515 | J23: =+AVERAGE(J11:J22) -> 0.075658259 | L23: =+J23-H23 -> 0.018752745 | N23: Euribor1year_3 | O23: 1 | P23: 0.00951 | Q23: 0.00026351 | R23: 36.08 | S23: <,0001
N24: Correlation of Estimates
N25: Variable | O25: Intercept | P25: Unemployment_Rate | Q25: GDP_9 | R25: Euribor1year_3
B26: Baseline Projection | N26: Intercept | O26: 1 | P26: -0.9949 | Q26: -0.094 | R26: -0.2017
H27: =+AVERAGE(H29:H45) -> 0.047226899 | N27: Unemployment_Rate | O27: -0.9949 | P27: 1 | Q27: 0.0878 | R27: 0.1459
B28: t | C28: intercept | D28: =+D10 -> Unemployment_Rate | E28: =+E10 -> GDP_9 | F28: =+F10 -> Euribor1year_3 | H28: TD12M Projected | N28: GDP_9 | O28: -0.094 | P28: 0.0878 | Q28: 1 | R28: -0.0112
B29: =+Portugal_indicadores!A75 -> 202508 | D29: =+Portugal_indicadores!T23 -> 6.2564356 | E29: =+Portugal_indicadores!R14 -> 1.4 | F29: =+Portugal_indicadores!W20 -> 1.956 | H29: =+$C$4+D29*$D$4+E29*$E$4+F29*$F$4 -> 0.04804112 | N29: Euribor1year_3 | O29: -0.2017 | P29: 0.1459 | Q29: -0.0112 | R29: 1
B30: =+Portugal_indicadores!A76 -> 202509 | D30: =+Portugal_indicadores!T24 -> 6.2564356 | E30: =+Portugal_indicadores!R15 -> 1.4 | F30: =+Portugal_indicadores!W21 -> 1.886 | H30: =+$C$4+D30*$D$4+E30*$E$4+F30*$F$4 -> 0.04737542 | N30: Generated by the SAS System ('SASMain', X64_SRV19) on August 29, 2025 at 12:37:31 PM | AM30: Valeurs réelles | AN30: Valeurs prédites
B31: =+Portugal_indicadores!A77 -> 202510 | D31: =+Portugal_indicadores!T25 -> 6.2095872 | E31: =+Portugal_indicadores!R16 -> -0.4 | F31: =+Portugal_indicadores!W22 -> 1.894 | H31: =+$C$4+D31*$D$4+E31*$E$4+F31*$F$4 -> 0.048043745 | AL31: DATE
B32: =+Portugal_indicadores!A78 -> 202511 | D32: =+Portugal_indicadores!T26 -> 6.2095872 | E32: =+Portugal_indicadores!R17 -> -0.4 | F32: =+Portugal_indicadores!W23 -> 1.908 | H32: =+$C$4+D32*$D$4+E32*$E$4+F32*$F$4 -> 0.048176885 | N32: Linear Regression Results | AL32: 45413 | AM32: 0.073365 | AN32: 0.077631
B33: =+Portugal_indicadores!A79 -> 202512 | D33: =+Portugal_indicadores!T27 -> 6.2095872 | E33: =+Portugal_indicadores!R18 -> -0.4 | F33: =+Portugal_indicadores!W24 -> 1.867 | H33: =+$C$4+D33*$D$4+E33*$E$4+F33*$F$4 -> 0.047786975 | N33: The REG Procedure | AL33: 45444 | AM33: 0.07471 | AN33: 0.078007
B34: =+Portugal_indicadores!A80 -> 202601 | D34: =+Portugal_indicadores!T28 -> 6.4 | E34: =+Portugal_indicadores!R19 -> 0.6 | F34: =+Portugal_indicadores!W25 -> 1.844 | H34: =+$C$4+D34*$D$4+E34*$E$4+F34*$F$4 -> 0.04763539 | N34: Model: Linear_Regression_Model | AL34: 45474 | AM34: 0.072452 | AN34: 0.077372 | AS34: TD12M estimated | AU34: TD12M observed (real) | AW34: Difference | AY34: power 2 | BA34: Sum | BC34: MSE | BE34: RMSE
B35: =+Portugal_indicadores!A81 -> 202602 | D35: =+Portugal_indicadores!T29 -> 6.4 | E35: =+Portugal_indicadores!R20 -> 0.6 | F35: =+Portugal_indicadores!W26 -> 1.875 | H35: =+$C$4+D35*$D$4+E35*$E$4+F35*$F$4 -> 0.0479302 | N35: Dependent Variable: TD_12M_Consolidado | AL35: 45505 | AM35: 0.072553 | AN35: 0.07515 | AR35: =B11 -> 202408 | AS35: =AN35 -> 0.07515 | AU35: =AM35 -> 0.072553 | AW35: =AU35-AS35 -> -0.002597 | AY35: =POWER(AW35,2) -> 6.744409e-06 | BA35: =SUM(AY35:AY50) -> 0.00057125719 | BC35: =(1/COUNT(AR35:AR49))*BA35 -> 4.7604766e-05 | BE35: =SQRT(BC35) -> 0.0068996207
B36: =+Portugal_indicadores!A82 -> 202603 | D36: =+Portugal_indicadores!T30 -> 6.4 | E36: =+Portugal_indicadores!R21 -> 0.6 | F36: =+Portugal_indicadores!W27 -> 1.763 | H36: =+$C$4+D36*$D$4+E36*$E$4+F36*$F$4 -> 0.04686508 | N36: Test of First and Second | AL36: 45536 | AM36: 0.069116 | AN36: 0.07169 | AR36: =B12 -> 202409 | AS36: =AN36 -> 0.07169 | AU36: =AM36 -> 0.069116 | AW36: =AU36-AS36 -> -0.002574 | AY36: =POWER(AW36,2) -> 6.625476e-06
B37: =+Portugal_indicadores!A83 -> 202604 | D37: =+Portugal_indicadores!T31 -> 6.4 | E37: =+Portugal_indicadores!R22 -> 1.85 | F37: =+Portugal_indicadores!W28 -> 2.097 | H37: =+$C$4+D37*$D$4+E37*$E$4+F37*$F$4 -> 0.049551733 | N37: Moment Specification | AL37: 45566 | AM37: 0.064833 | AN37: 0.070652 | AR37: =B13 -> 202410 | AS37: =AN37 -> 0.070652 | AU37: =AM37 -> 0.064833 | AW37: =AU37-AS37 -> -0.005819 | AY37: =POWER(AW37,2) -> 3.3860761e-05 | BE37: =0.0061/AU37 -> 0.094087887
B38: =+Portugal_indicadores!A84 -> 202605 | D38: =+Portugal_indicadores!T32 -> 6.4 | E38: =+Portugal_indicadores!R23 -> 1.85 | F38: =+Portugal_indicadores!W29 -> 1.971 | H38: =+$C$4+D38*$D$4+E38*$E$4+F38*$F$4 -> 0.048353473 | N38: DF | O38: Chi-Square | P38: Pr > ChiSq | AL38: 45597 | AM38: 0.061169 | AN38: 0.068444 | AR38: =B14 -> 202411 | AS38: =AN38 -> 0.068444 | AU38: =AM38 -> 0.061169 | AW38: =AU38-AS38 -> -0.007275 | AY38: =POWER(AW38,2) -> 5.2925625e-05
B39: =+Portugal_indicadores!A85 -> 202606 | D39: =+Portugal_indicadores!T33 -> 6.4 | E39: =+Portugal_indicadores!R24 -> 1.85 | F39: =+Portugal_indicadores!W30 -> 1.899 | H39: =+$C$4+D39*$D$4+E39*$E$4+F39*$F$4 -> 0.047668752 | N39: 9 | O39: 13.77 | P39: 0.1309 | AL39: 45627 | AM39: 0.058175 | AN39: 0.066635 | AR39: =B15 -> 202412 | AS39: =AN39 -> 0.066635 | AU39: =AM39 -> 0.058175 | AW39: =AU39-AS39 -> -0.00846 | AY39: =POWER(AW39,2) -> 7.15716e-05
B40: =+Portugal_indicadores!A86 -> 202607 | D40: =+Portugal_indicadores!T34 -> 6.4 | E40: =+Portugal_indicadores!R25 -> 1.78 | F40: =+Portugal_indicadores!W31 -> 1.805 | H40: =+$C$4+D40*$D$4+E40*$E$4+F40*$F$4 -> 0.046802235 | N40: Durbin-Watson D | O40: 0.539 | AL40: 45658 | AM40: 0.060101 | AN40: 0.06797 | AR40: =B16 -> 202501 | AS40: =AN40 -> 0.06797 | AU40: =AM40 -> 0.060101 | AW40: =AU40-AS40 -> -0.007869 | AY40: =POWER(AW40,2) -> 6.1921161e-05
B41: =+Portugal_indicadores!A87 -> 202608 | D41: =+Portugal_indicadores!T35 -> 6.4 | E41: =+Portugal_indicadores!R26 -> 1.78 | F41: =+Portugal_indicadores!W32 -> 1.793 | H41: =+$C$4+D41*$D$4+E41*$E$4+F41*$F$4 -> 0.046688115 | N41: Number of Observations | O41: 49 | AL41: 45689 | AM41: 0.056903 | AN41: 0.066606 | AR41: =B17 -> 202502 | AS41: =AN41 -> 0.066606 | AU41: =AM41 -> 0.056903 | AW41: =AU41-AS41 -> -0.009703 | AY41: =POWER(AW41,2) -> 9.4148209e-05
...

Sheet gdp
A1: Quarterly real GDP growth - OECD countries | I1: (DSD_EO@DF_EO) Economic Outlook 117 | J1: OECD Data Explorer • Economic Outlook 117
A2: Frequency of observation: | B2: OECD Data Explorer • Quarterly real GDP growth - OECD countries | I2: (REF_AREA) Reference area:
A3: Quarterly | I3: (PRT) Portugal
A4: Reference area: | I4: (MEASURE) Measure:
A5: Portugal | I5: (GDPV_ANNPCT) Gross domestic product, volume, growth
A6: Combined transaction: | I6: (FREQ) Frequency of observation:
A7: Gross domestic product, Total economy | I7: (Q) Quarterly
A8: Combined unit of measure: | I8: (COMBINED_UNIT_MEASURE) Combined unit of measure:
A9: Growth rate, period on period, Chain linked volume, Calendar and seasonally adjusted | I9: (PA, 2021) Percent per annum, 2021
A10: Time period | I10: (TIME_PERIOD) Time period
A11: 2019-Q1 | C11: 0.9 | D11: 0.9 | I11: (2019-Q1) 2019-Q1 | K11: 3.55
A12: 2019-Q2 | C12: 0.6 | D12: 0.6 | I12: (2019-Q2) 2019-Q2 | K12: 2.52
A13: 2019-Q3 | C13: 0.4 | D13: 0.4 | I13: (2019-Q3) 2019-Q3 | K13: 1.55
A14: 2019-Q4 | C14: 0.8 | D14: 0.8 | I14: (2019-Q4) 2019-Q4 | K14: 3.2
A15: 2020-Q1 | C15: -4.2 | D15: -4.2 | I15: (2020-Q1) 2020-Q1 | K15: -15.6
A16: 2020-Q2 | C16: -15.0 | D16: -15 | I16: (2020-Q2) 2020-Q2 | K16: -47.9
A17: 2020-Q3 | C17: 14.4 | D17: 14.4 | I17: (2020-Q3) 2020-Q3 | K17: 71.1
A18: 2020-Q4 | C18: 0.2 | D18: 0.2 | I18: (2020-Q4) 2020-Q4 | K18: 0.94
A19: 2021-Q1 | C19: -2.8 | D19: -2.8 | I19: (2021-Q1) 2021-Q1 | K19: -10.81
A20: 2021-Q2 | C20: 4.6 | D20: 4.6 | I20: (2021-Q2) 2021-Q2 | K20: 19.6
A21: 2021-Q3 | C21: 3.6 | D21: 3.6 | I21: (2021-Q3) 2021-Q3 | K21: 15.17
A22: 2021-Q4 | C22: 1.9 | D22: 1.9 | I22: (2021-Q4) 2021-Q4 | K22: 7.67
... A36: 2025-Q2 | C36: 0.6 | D36: 0.6 | I36: (2025-Q2) 2025-Q2 | K36: 3.45
A37: (2025-Q3) 2025-Q3 | B37: forecast | C37: 1.9 | I37: (2025-Q3) 2025-Q3 | K37: 1.85
A38: (2025-Q4) 2025-Q4 | B38: forecast | C38: 1.8 | I38: (2025-Q4) 2025-Q4 | K38: 1.78
A39: (2026-Q1) 2026-Q1 | B39: forecast | C39: 1.9 | I39: (2026-Q1) 2026-Q1 | K39: 1.79
A40: (2026-Q2) 2026-Q2 | B40: forecast | C40: 1.9 | I40: (2026-Q2) 2026-Q2 | K40: 1.87
A41: (2026-Q3) 2026-Q3 | B41: forecast | C41: 1.9 | I41: (2026-Q3) 2026-Q3 | K41: 1.95
A42: (2026-Q4) 2026-Q4 | B42: forecast | C42: 2 | I42: (2026-Q4) 2026-Q4 | K42: 1.97
